Watching for file changes with StatReloader
Exception in thread django-main-thread:
Traceback (most recent call last):
  File "/Library/Developer/CommandLineTools/Library/Frameworks/Python3.framework/Versions/3.8/lib/python3.8/threading.py", line 932, in _bootstrap_inner
    self.run()
  File "/Library/Developer/CommandLineTools/Library/Frameworks/Python3.framework/Versions/3.8/lib/python3.8/threading.py", line 870, in run
    self._target(*self._args, **self._kwargs)
  File "/Library/Python/3.8/site-packages/django/utils/autoreload.py", line 53, in wrapper
    fn(*args, **kwargs)
  File "/Library/Python/3.8/site-packages/django/core/management/commands/runserver.py", line 117, in inner_run
    self.check(display_num_errors=True)
  File "/Library/Python/3.8/site-packages/django/core/management/base.py", line 392, in check
    all_issues = self._run_checks(
  File "/Library/Python/3.8/site-packages/django/core/management/base.py", line 382, in _run_checks
    return checks.run_checks(**kwargs)
  File "/Library/Python/3.8/site-packages/django/core/checks/registry.py", line 72, in run_checks
    new_errors = check(app_configs=app_configs)
  File "/Library/Python/3.8/site-packages/django/core/checks/urls.py", line 13, in check_url_config
    return check_resolver(resolver)
  File "/Library/Python/3.8/site-packages/django/core/checks/urls.py", line 23, in check_resolver
    return check_method()
  File "/Library/Python/3.8/site-packages/django/urls/resolvers.py", line 406, in check
    for pattern in self.url_patterns:
  File "/Library/Python/3.8/site-packages/django/utils/functional.py", line 48, in __get__
    res = instance.__dict__[self.name] = self.func(instance)
  File "/Library/Python/3.8/site-packages/django/urls/resolvers.py", line 587, in url_patterns
    patterns = getattr(self.urlconf_module, "urlpatterns", self.urlconf_module)
  File "/Library/Python/3.8/site-packages/django/utils/functional.py", line 48, in __get__
    res = instance.__dict__[self.name] = self.func(instance)
  File "/Library/Python/3.8/site-packages/django/urls/resolvers.py", line 580, in urlconf_module
    return import_module(self.urlconf_name)
  File "/Library/Developer/CommandLineTools/Library/Frameworks/Python3.framework/Versions/3.8/lib/python3.8/importlib/__init__.py", line 127, in import_module
    return _bootstrap._gcd_import(name[level:], package, level)
  File "<frozen importlib._bootstrap>", line 1014, in _gcd_import
  File "<frozen importlib._bootstrap>", line 991, in _find_and_load
  File "<frozen importlib._bootstrap>", line 975, in _find_and_load_unlocked
  File "<frozen importlib._bootstrap>", line 671, in _load_unlocked
  File "<frozen importlib._bootstrap_external>", line 783, in exec_module
  File "<frozen importlib._bootstrap>", line 219, in _call_with_frames_removed
  File "/Users/keypat/django4proj/django4proj/urls.py", line 18, in <module>
    from users import urls
  File "/Users/keypat/django4proj/users/urls.py", line 3, in <module>
    from . import views
  File "/Users/keypat/django4proj/users/views.py", line 12, in <module>
    from rest_framework.decorators import list_route
ImportError: cannot import name 'list_route' from 'rest_framework.decorators' (/Library/Python/3.8/site-packages/rest_framework/decorators.py)
/Users/keypat/django4proj/users/views.py changed, reloading.
Performing system checks...

Watching for file changes with StatReloader
Exception in thread django-main-thread:
Traceback (most recent call last):
  File "/Library/Developer/CommandLineTools/Library/Frameworks/Python3.framework/Versions/3.8/lib/python3.8/threading.py", line 932, in _bootstrap_inner
    self.run()
  File "/Library/Developer/CommandLineTools/Library/Frameworks/Python3.framework/Versions/3.8/lib/python3.8/threading.py", line 870, in run
    self._target(*self._args, **self._kwargs)
  File "/Library/Python/3.8/site-packages/django/utils/autoreload.py", line 53, in wrapper
    fn(*args, **kwargs)
  File "/Library/Python/3.8/site-packages/django/core/management/commands/runserver.py", line 117, in inner_run
    self.check(display_num_errors=True)
  File "/Library/Python/3.8/site-packages/django/core/management/base.py", line 392, in check
    all_issues = self._run_checks(
  File "/Library/Python/3.8/site-packages/django/core/management/base.py", line 382, in _run_checks
    return checks.run_checks(**kwargs)
  File "/Library/Python/3.8/site-packages/django/core/checks/registry.py", line 72, in run_checks
    new_errors = check(app_configs=app_configs)
  File "/Library/Python/3.8/site-packages/django/core/checks/urls.py", line 13, in check_url_config
    return check_resolver(resolver)
  File "/Library/Python/3.8/site-packages/django/core/checks/urls.py", line 23, in check_resolver
    return check_method()
  File "/Library/Python/3.8/site-packages/django/urls/resolvers.py", line 406, in check
    for pattern in self.url_patterns:
  File "/Library/Python/3.8/site-packages/django/utils/functional.py", line 48, in __get__
    res = instance.__dict__[self.name] = self.func(instance)
  File "/Library/Python/3.8/site-packages/django/urls/resolvers.py", line 587, in url_patterns
    patterns = getattr(self.urlconf_module, "urlpatterns", self.urlconf_module)
  File "/Library/Python/3.8/site-packages/django/utils/functional.py", line 48, in __get__
    res = instance.__dict__[self.name] = self.func(instance)
  File "/Library/Python/3.8/site-packages/django/urls/resolvers.py", line 580, in urlconf_module
    return import_module(self.urlconf_name)
  File "/Library/Developer/CommandLineTools/Library/Frameworks/Python3.framework/Versions/3.8/lib/python3.8/importlib/__init__.py", line 127, in import_module
    return _bootstrap._gcd_import(name[level:], package, level)
  File "<frozen importlib._bootstrap>", line 1014, in _gcd_import
  File "<frozen importlib._bootstrap>", line 991, in _find_and_load
  File "<frozen importlib._bootstrap>", line 975, in _find_and_load_unlocked
  File "<frozen importlib._bootstrap>", line 671, in _load_unlocked
  File "<frozen importlib._bootstrap_external>", line 783, in exec_module
  File "<frozen importlib._bootstrap>", line 219, in _call_with_frames_removed
  File "/Users/keypat/django4proj/django4proj/urls.py", line 18, in <module>
    from users import urls
  File "/Users/keypat/django4proj/users/urls.py", line 3, in <module>
    from . import views
  File "/Users/keypat/django4proj/users/views.py", line 12, in <module>
    from rest_framework.decorators import detail_route
ImportError: cannot import name 'detail_route' from 'rest_framework.decorators' (/Library/Python/3.8/site-packages/rest_framework/decorators.py)
